Workbook

Sheet Synthèse
A1: Macro processus | B1: Micro processus | C1: Tâches
A2: Big Data & Data Gouvernance (Network & IS) | B2: ='Big Data & Gouvernance'!B35 -> 6 | C2: ='Big Data & Gouvernance'!D35 -> 27
A3: Conception & Ingénierie Networks & IS | B3: ='Conception & ingénierie'!B31 -> 6 | C3: ='Conception & ingénierie'!D31 -> 25
A4: Déploiement & Extension Infrastructure Networks & IS | B4: ='Déploiement & extension infra'!B41 -> 7 | C4: ='Déploiement & extension infra'!D41 -> 34
A5: Digitalisation Networks & IS | B5: =Digitalisation!B28 -> 5 | C5: =Digitalisation!D28 -> 20
A6: Exploitation & Maintenance Infrastructure Networks & IS | B6: =+'Exploitation et maint infra'!B40 -> 6 | C6: =+'Exploitation et maint infra'!D40 -> 33
A7: Gestion budgétaire(Investissement et Opérationnel) | B7: ='Gestion budgétaire'!B39 -> 8 | C7: ='Gestion budgétaire'!D39 -> 33
A8: Gouvernance Networks & IS | B8: ='Gouvernance N&IS'!B43 -> 6 | C8: ='Gouvernance N&IS'!D43 -> 36
A9: Management des Projets Networks & IS | B9: ='Projets N&IS'!B72 -> 13 | C9: ='Projets N&IS'!D72 -> 64
A10: Performance & Optimisation Networks & IS | B10: ='Performance & optimisation'!B33 -> 6 | C10: ='Performance & optimisation'!D33 -> 26
A11: Sécurité & Résilience des Systèmes d’Information Networks & IS | B11: =+'Sécurité & Résilience SI'!B47 -> 10 | C11: =+'Sécurité & Résilience SI'!D47 -> 43
A12: Stratégie & Évolution des Infrastructures et Services | B12: =+'Stratégie & Evolution des infra'!B26 -> 5 | C12: =+'Stratégie & Evolution des infra'!D26 -> 20
A13: Support & Assistance IT Network & IS | B13: =+'Support et Assistance IT'!B31 -> 6 | C13: =+'Support et Assistance IT'!D31 -> 24
A14: Support Opérationnel aux Activités Networks & IS | B14: =+'Support opérationnel aux activi'!B23 -> 4 | C14: =+'Support opérationnel aux activi'!D23 -> 18
A15: =COUNTA(A2:A14) -> 13 | B15: =SUM(B2:B14) -> 88 | C15: =SUM(C2:C14) -> 403

Sheet Big Data & Gouvernance
A1: Macro 13: Big Data & Data Gouvernance (Network & IS)
A3: Description Détaillée | B3: Process | C3: Description du process | D3: Identification des tâches | E3: Directions concernées
A4: Cette macro regroupe l’ensemble des activités liées à la gestion des données & métadonnées dans l’écosystème technique et SI, depuis leur collecte jusqu’à leur valorisation métier. Elle s’inscrit dans les pratiques de Data Lifecycle Management en cohérence avec les référentiels eTOM (notamment AIM - Application, Information and Data Management) et ITIL (Service Operation, Continual Service Improvement). Elle couvre la collecte et la consolidation des données issues des réseaux (fixes, mobiles), des systèmes IT, et des plateformes de service, via des pipelines d’ingestion adaptés. Elle intègre le stockage structuré et non structuré, la gestion rigoureuse des données & métadonnées, la gouvernance des accès, ainsi que la surveillance de la performance des environnements Big Data. La macro inclut également les usages analytiques des données pour optimiser les performances, anticiper les incidents, améliorer les services ou appuyer les décisions stratégiques. Enfin, elle encadre l’innovation basée sur la donnée et la conduite de projets Big Data, garantissant alignement métier et efficacité technologique. | B4: Processus de collecte, ingestion et intégration des données | C4: Assurer la collecte, l'ingestion et l’intégration continue et fiable des données issues de différentes sources internes et externes au datalake et au datawarehouse de l’entreprise. | D4: Identifier les sources de données (réseaux, IT, services) | E4: Big Data & Data Gouvernance
D5: Mettre en œuvre les mécanismes d'igestion (connecteurs, API, agents)
D6: Nettoyer, formater et normaliser les flux de données
D7: Charger les données dans les environnements de traitement (data lake, entrepôts)
B8: Processus de stockage et gestion des données & métadonnées | C8: Ce Process concerne le stockage, l’organisation, la gouvernance, la sécurisation et la mise à disposition des données. Il garantit que les données soient accessibles, fiables et conformes aux exigences métier et réglementaires. | D8: Organiser les espaces de stockage adaptés (fichiers, bases, entrepôts) | E8: Big Data & Data Gouvernance
D9: Mettre en œuvre les règles de rétention, archivage et purge
D10: Maintenir les catalogues de données et les dictionnaires de métadonnées
D11: Appliquer les droits d’accès et politiques de confidentialité
D12: La mise à disposition et l’exploitation des données
B13: Processus d’exploitation et valorisation des données | C13: Le macro-processus regroupe l’ensemble des activités permettant de transformer les données en informations exploitables pour la prise de décision, l’optimisation des opérations et l’innovation via l’analytique avancée, la Business Intelligence (BI), le Machine Learning (ML) et l’Intelligence Artificielle (IA). Il vise à extraire du sens des données, automatiser les analyses et fournir des insights stratégiques aux métiers | D13: Concevoir des tableaux de bord opérationnels et décisionnels | E13: Big Data & Data Gouvernance
D14: Réaliser des analyses croisées (trafic, incidents, QoS, usages)
D15: Développer des modèles statistiques ou prédictifs (BI, IA,ML)
D16: Automatiser les ajustements des algorithmes, et workflows analytiques
D17: Concevoir des modèles expérimentaux pour tester différentes hypothèses et stratégies sur les clients (ex. changements dans les tarifs ou dans les services proposés).
D18: Publier des rapports périodiques ou à la demande
B19: Processus de surveillance et optimisation des performances Big Data /DWH | C19: Le macro-processus "Surveillance et Optimisation des Performances de la plateforme Big Data/DWH" regroupe l’ensemble des activités permettant de superviser, analyser et optimiser la performance des infrastructures et des traitements de données. Il vise à garantir la disponibilité, la scalabilité et l'efficacité du système Big Data / DWH en s’appuyant sur le monitoring en temps réel, l’optimisation des ressources et la gestion proactive des incidents. | D19: Superviser l’écosystème Big Data / DWH | E19: Big Data & Data Gouvernance
D20: Identifier les anomalies ou points de saturation
D21: Gérer les ressources et scalabilté
D22: Documenter et tracer les optimisations mises en œuvre
D23: Capitaliser sur les innovations réussies pour les industrialiser
D24: Automatisation et gestion pro-active des incidents (Détection automatique des pannes, actions correctives, processus de gestion des incidents).
D25: Monter en compétence des équipes
B27: Processus de gestion des projets Big Data (SI) | C27: Ce processus concerne la gestion des projets liés à l’exploitation du Big Data, de la conception à la mise en production dans le respect des exigences métiers. | D27: Identifier les projets stratégiques où l’utilisation du Big Data peut générer de la valeur ajoutée (ex. optimisation du réseau, analyse comportementale des clients, détection de fraudes). | E27: Big Data & Data Gouvernance
D28: Sélectionner et déployer les technologies Big Data (Hadoop, Spark, NoSQL, etc.) pour stocker et traiter de grandes quantités de données.
D29: Piloter les projets Big Data
B32: Processus d’innovation et transformation numérique | C32: Ce processus s'inscrit dans la vision stratégique à long terme de l’opérateur télécom pour intégrer de nouvelles technologies et transformer les modèles d'affaires grâce à la donnée. | D32: Assurer la veille technologique et innovation | E32: Big Data & Data Gouvernance
D33: Mettre en œuvre de projets pour transformer les processus internes et améliorer les interactions avec les clients en utilisant les données (ex. chatbots, recommandations personnalisées).
B35: =COUNTA(B4:B33) -> 6 | D35: =COUNTA(D4:D33) -> 27

Sheet Conception & ingénierie
A1: Macro 05: Conception & Ingénierie Networks & IS
A3: Description Détaillée | B3: Process | C3: Description du process | D3: Identification des tâches | E3: Directions concernées
A4: Ce macro-processus s’inscrit dans les pratiques "Service Design" d’ITIL et "Infrastructure Lifecycle Management" d’eTOM, tout en preparant le terrain au déploiement et en garantissant que les solutions techniques à mettre en œuvre soient cohérentes, performantes, sécurisées et conformes aux normes réquises. Il débute par la définition des besoins et l’analyse de faisabilité, qui permet d’identifier les exigences Networks &IS et d’évaluer leur faisabilité sur les plans technique, budgetaire et environnemental. Il suit la conception d’architecture Networks &IS , où sont définis la topologie cible, les protocoles, les principes de sécurité et d’interconnexion avec les systèmes OSS/BSS. L’ingénierie détaillée prend ensuite le relais pour produire les plans techniques opérationnels (schémas FO, configurations IP, dimensionnements, etc.). Ce travail alimente le choix des ressources, permettant d’établir les BoM et BoQ adaptés. Avant de passer au déploiement, une revue de conception et validation technique est réalisée pour garantir la conformité aux exigences techniques, HSE et performance. Enfin, le transfert vers les équipes de déploiement assure une passation complète et documentée des livrables (plans, configurations, scripts) vers les deploiements et les extensions . Chaque processus s’enchaîne de manière fluide, l’output de l’un devenant l’input du suivant, assurant une traçabilité et une qualité de conception bout-en-bout. | B4: Process de définition des besoins metiers et analyse de faisabilité | C4: Identifier et qualifier tous les besoins , et évaluer leur faisabilité | D4: Recueillir les besoins métiers (projets, évolution, couverture, capacité, veille technologique) | E4: Direction Network Engineering IT Product & Project Delivery
D5: Traduire les besoins en exigences techniques (Radio, Transmission, FO, IP, IT, Énergie etc...)
D6: Réaliser l’analyse de faisabilité technique et financière
D7: Intégrer les contraintes environnementales et réglementaires
B8: Processus de conception des architectures Networks &IS | C8: Concevoir une solution cible alignée avec les standards et les exigences | D8: Élaborer la topologie réseau et les choix technologiques | E8: Direction Network Engineering IT Product & Project Delivery
D9: Définir les principes de redondance, sécurisation et interopérabilité
D10: Documenter les interfaces OSS/BSS et les dépendances techniques
D11: Élaborer les diagrammes d’architecture et plans logiques.
B12: Processus de réalisation des plans d'Ingénierie détaillée | C12: Produire les plans techniques et configurations détaillées. | D12: Elaborer dans les détails les schémas de câblage et d’architecture physique | E12: Direction Network Engineering IT Product & Project Delivery
D13: Générer les configurations types avec tous les détailles.
D14: Dimensionner les capacités et calculer les marges techniques
D15: Dcumenter les fiches techniques et guides d’installation
B16: Processus de d'identification des ressources (BoM/BoQ) | C16: Identifier l’ensemble des ressources matérielles, humaines , logicielles et licences nécessaires . | D16: Lister les équipements actifs/passifs requis | E16: Direction Network Engineering IT Product & Project Delivery
D17: Évaluer les quantités nécessaire par projet .
D18: Estimer les versions logicielles et les licences associées
D19: Valider les prérequis avec les standards opérateur.
B20: Processus de validation technique et revue de conception | C20: Garantir la conformité et la robustesse technique du design avant déploiement. | D20: Organiser une revue technique multi-acteurs | E20: Direction Network Engineering IT Product & Project Delivery
D21: Contrôler la conformité avec les normes internes et HSE
D22: Documenter les écarts et ajuster les plans si nécessaire.
D23: Valider officiellement la conception pour transfert.
B24: Processus de Hand-over vers le déploiement | C24: Assurer la transmission complète et traçable du dossier d’ingénierie pour mise en œuvre. | D24: Compiler le Design Package (plans, schémas, BoM/BoQ, scripts, fiches). | E24: Direction Network Engineering IT Product & Project Delivery
D25: Réaliser la revue et une réunion de transfert avec les équipes de deploiement .
D26: Fournir les jeux de configuration et consignes d’intégration.
D27: Archiver les documents validés dans le référentiel documentaire.
D28: Obtenir le GO pourr le deploiement .
B31: =COUNTA(B4:B28) -> 6 | D31: =COUNTA(D4:D28) -> 25

Sheet Déploiement & extension infra
A1: Macro 06: Déploiement & Extension Infrastructure Networks & IS
A3: Description Détaillée | B3: Process | C3: Description du process | D3: Identification des tâches | E3: Directions concernées
A4: Cette macro englobe l’ensemble des activités permettant de réaliser les architectures conçues en infrastructures réellement opérationnelles, tant sur les réseaux mobiles, fixes, de transport, que sur les plateformes informatiques (serveurs, virtualisation, stockage etc). Elle couvre le cycle complet de mise en œuvre, extension, modernisation des ressources physiques et logiquesjusqu'a leurs mise en service . Elle débute après la phase d’ingénierie, et s’inscrit dans le domaine « Capacity & Resource Delivery » de l’eTOM et le domaine « Service Transition » de l’ITIL v4. Elle garantit que les solutions sont livrées en conformité avec les exigences de performance, qualité de service, sécurité et continuité, tout en assurant une coordination rigoureuse entre les équipes projet, terrain, support et fournisseurs. Les étapes clés incluent : la planification détaillée du déploiement, la réservation et le provisioning des ressources, l’installation et la configuration des équipements, l’intégration dans l’écosystème existant, les tests d’acceptance, la documentation finale et le hand‑over vers l’exploitation. | B4: Processus de planification des déploiements | C4: Définir et organiser les lots de déploiement ou d’extension des infrastructures Radio, FH/FO, IP/MPLS, Core et plateforme etc,en cohérence avec les capacités, priorités projets et contraintes opérationnelles & budgetaires. | D4: Définir le périmètre du déploiement (type de services, zones, sites, etc) | E4: Direction Network Engineering Direction Infrastructure Infrastructure IT IT Product & Project Delivery Direction PMO & Gouvernance
D5: Consolider les besoins issus de l’ingénierie et du capacity planning
D6: Élaborer le plan directeur de déploiement (phases, priorités, jalons)
D7: Évaluer les impacts sur les systèmes existants
D8: Coordonner toutes les parties prenantes ( Internes et Externes)
D9: Organiser la gouvernance projet et le pilotage interdomaines
B10: Processus de provisionning des ressources | C10: Mettre à disposition les ressources physiques, logicielles, humaines et virtuelles nécessaires au déploiement des infrastructures et services, tout en prevoyant la mise à disposition d'un stock minimal en PDR pour la maintenance | D10: Émettre les commandes d’équipements (BBU, RRU, MW, routers, servers, licences VM, middleware etc,,,) | E10: Direction Network Engineering Direction Infrastructure Infrastructure IT IT Product & Project Delivery Direction Technical Business Support
D11: Assurer la gestion logistique (réception, entreposage, acheminement site, suivi de lot)
D12: Préparer les configurations initiales (preload, scripts initiaux)
D13: Faire les previsions techniques (Réserver les adresses IP, VLAN, numérotations)
D14: Valider la disponibilité et la conformité des ressources allouées ,
B15: Processus d’installation et de déploiement sur site | C15: Réaliser l’installation physique et la mise en service des éléments passifs et actifs (énergie, FH/FO, antennes, IP nodes, serveurs) selon les standards opérateur et exigences de sécurité. | D15: Effectuer la mise en place de l’infrastructure passive (armoire, ODF, DDF, chemins de câbles, grounding) | E15: Direction Network Engineering Direction Infrastructure Infrastructure IT
D16: Installer les équipements actifs (RBS/eNB/gNB, routers, switches, firewalls, serveurs, stockage)
D17: Réaliser les liaisons FH/FO, les tests d’atténuation et d’alimentation
D18: Vérifier la connectivité intrasite et intersite
D19: Valider l’installation physique conforme aux plans
B20: Processus de configuration, intégration réseau et interconnexion | C20: Configurer les équipements déployés et assurer leur intégration dans les réseaux existants (radio, transport, cœur, IT) et dans les systèmes de gestion (OSS, BSS...). | D20: Charger les configurations initiales (paramètres RF, IP, VLAN, routage, sécurité) | E20: Direction Network Engineering Direction Infrastructure Infrastructure IT IT Product & Project Delivery
D21: Effectuer les intégrations dans les contrôleurs (BSC, RNC, eNB, gNB, routers, EPC, 5GC)
D22: Enregistrer les équipements dans les outils OSS (ENM, U2000, SolarWinds, etc.)
D23: Connecter les serveurs/VM aux environnements applicatifs et bases de données
D24: Vérifier la communication bidirectionnelle OSS ↔ SI (alarme, inventaire, PM)
B25: Processus de tests et mise en service opérationnelle | C25: Assurer la conformité technique et fonctionnelle du déploiement à travers des tests d’acceptance couvrant les couches physiques, IP, applicatives et de service, avant bascule en production. | D25: Élaborer les plans de tests (fonctionnels, charge, QoS) | E25: Direction Network Engineering Direction Infrastructure Infrastructure IT IT Product & Project Delivery
D26: Vérifier la QoS (KPIs RSRP, SINR, RTT, throughput, CPU/Memory)
D27: Effectuer les tests des services de bout en bout (service voice, data, signaling, API)
B28: Processus d'Acceptance | C28: verifier et valider les aspects techniques des deploiements et des extensions , | D28: contrôler la conformité des installations | E28: Direction Network Engineering
D29: effectuer des tests technique necessaire | E29: Direction Infrastructure
D30: Documenter les résultats et écarts | E30: Infrastructure IT
D31: Signer les PV d’acceptance | E31: IT Product & Project Delivery
B32: Processus de transfert aux opérations et clôture projet | C32: Documenter l’ensemble du déploiement (infrastructures, configurations, résultats de tests) et assurer le transfert complet( Document ,PDR,Competences) vers les entités d’exploitation, de supervision et de support applicatif | D32: Compiler les livrables techniques (plans, configs, PV, logs) | E32: Direction Network Engineering Direction Infrastructure Infrastructure IT IT Product & Project Delivery Direction Core Network (iSOC + Métiers) IT Operations
D33: Mettre à jour la CMDB et les inventaires réseau/SI
D34: Integrer les nouveau équipements et extensions dans les outils de suppervision
D35: Effectuer le transfert (Responsabilité, Document ,PDRetc,,,) vers les equipes metier et de supervision
D36: Effectuer le transfert de compétence via des formations adaptées aux équipes d'exploitation et de supervision
D37: Clôturer le projet dans le portefeuille de déploiement et capitaliser les retours d’expérience
B41: =COUNTA(B4:B37) -> 7 | D41: =COUNTA(D4:D37) -> 34

Sheet Digitalisation
A2: Macro 12 : Digitalisation Networks & IS
A4: Description Détaillée | B4: Process | C4: Description du process | D4: Identification des tâches | E4: Directions concernées
A5: Cette macro couvre l’ensemble des activités visant à automatiser, digitaliser et moderniser les processus, outils et services N&IS avec une exigence sur leurs securités et conformités . Elle inclut la conception et le déploiement de solutions de digitalisation, l’automatisation des workflows techniques (provisioning, supervision etc,,,), l’intégration d’outils DevOps/NetOps, et la mise en œuvre de portails utilisateurs et self-service. Elle s’aligne sur les bonnes pratiques eTOM et ITIL . Son objectif est d’améliorer la rapidité d’exécution, la qualité des services, la réduction des tâches manuelles, et de renforcer l’agilité opérationnelle des équipes techniques. | B5: Processus d'agilité des Projets de digitalisation | C5: Piloter efficacement les projets de développement logiciel en assurant flexibilité, réactivité et collaboration avec les parties prenantes. | D5: Gestion des sprints (Scrum, Kanban) : Planification, backlog, daily meetings. | E5: Digital & Innovation
D6: Collaboration et suivi : Utilisation d’outils comme JIRA, Confluence, MS PROJECTS..
D7: Priorisation des tâches : Affectation et suivi des tickets de développement
D8: Suivi des indicateurs (KPI) : Mesure de la vélocité, qualité du code, délais.
B9: Cycle de vie du développement logiciel (SDLC) | C9: Identifier, analyser et digitaliser les processus manuels des équipes réseaux et IT. | D9: Analyse des besoins | E9: Digital & Innovation
D10: Conception &Développement
D11: Gestion du code source
D12: Tester ,Valider,deployer,monitorer et Maintenir
B13: DevOps & Intégration Continue/Déploiement Continu (CI/CD) | C13: Automatiser et fludifier les tâches techniques répétitives ou critiques (provisioning, patching, configuration). | D13: Identifier les tâches récurrentes à fort volume | E13: Digital & Innovation
D14: Développer les scripts ou playbooks d'automatisation
D15: Intégrer les outils dans les chaînes CI/CD
D16: Tester et déployer en production contrôlée
B17: Processus de Modernisation des applications métiers | C17: Mettre en œuvre des transitions vers des solutions numériques avancées pour ameliorer leurs sécurités et compatibilité avec les nouvelles technologies. (applications mobiles, portails self-service). | D17: Évaluer les besoins d’orchestration (multi-domaines) | E17: Digital & Innovation
D18: Sélectionner et paramétrer les orchestrateurs
D19: Intégrer les outils aux SI existants (OSS/BSS)
D20: Monitorer l’exécution des processus automatisés
B21: Processus de Gestion de la securité et conformité des applications | C21: Garantir la sécurité des logiciels et des données, en conformité avec les réglementations et standards du secteur télécom. | D21: Tests de sécurité | E21: Digital & Innovation
D22: Gestion des accès et identités
D23: Chiffrement et protection des données
D24: Conformité réglementaire : Respect des normes GDPR, ISO 27001, PCI-DSS
B28: =COUNTA(B5:B24) -> 5 | D28: =COUNTA(D5:D24) -> 20

Sheet Exploitation et maint infra
A2: Macro 07 : Exploitation & Maintenance Infrastructure Networks & IS
A3: Description Détaillée | B3: Process | C3: Description du process | D3: Identification des tâches | E3: Directions concernées
A4: Cette macro regroupe l’ensemble des activités nécessaires pour assurer le fonctionnement continu, la surveillance, la maintenance corrective& préventive et les changements sur les infrastructures N&IS, tout en garantissant la QoS. Elle couvre la coordination avec les ressources support. Elle s’appuie sur les processus Operations d’eTOM et sur les best practice d’ITIL (Incident, Event, Problem, Access, Request). Elle vise à restaurer le service le plus vite possible, minimiser les interruptions, anticiper les pannes, optimiser la fiabilité, reduire les pannes recurenttes et prolonger la durée de vie des équipements. Les principales activités sont : - Surveillance et détection d’incidents & problemes (Critique , Majeur , mineur ) sur les équipements, liens et les services via les les plateformes dediées - Gestion des incidents : priorisation, diagnostic, escalade, résolution, communication, clôture. - Gestion des problèmes : identification de causes profondes, suivi des actions correctives. - Gestion des changements : Pilotation des demandes de changement de bout en bout - Maintenance curative et préventive - Analyse de fiabilité et tendances (Suivi Indicateurs) : suivi des indicateurs (DR1,DR2,MTTR, MTBF, taux de panne, taux de disponibilité etc. . . ) - Interface avec les équipes de support (Logistique, prestataire, Business support, Gestion des pièces de rechange et la planification des interventions) '-Gestion des pièces de rechange et la planification des interventions - Documentation et reporting : mise à jour de la base de connaissance des incidents. Cette macro assure que les services délivrés sont disponibles, fiables et performants, tout en anticipant les dégradations et en pilotant l’amélioration continue. | B4: Processus de supervision | C4: Surveiller en temps réel l’état des équipements, services et ressources réseaux et IT pour détecter les anomalies ou dégradations. | D4: Collecter les evenements via les outils de monitoring | E4: Direction Core Operations(iSOC) IT Operations(iSOC)
D5: Détecter les alarmes et événements anormaux
D6: Corréler les alertes multi-domaines
D7: Qualifier et prioriser les événements
B8: Processus de gestion des incidents | C8: Gérer les incidents pour restaurer le service le plus rapidement possible tout en limitant l’impact sur les utilisateurs ou systèmes. | D8: Enregistrer les incidents détectés ou déclarés et le classifier | E8: Direction Core Operations(iSOC) IT Operations(iSOC)
D9: Diagnostiquer la cause immédiate
D10: Réaliser les actions de niveau 1 si necessaire
D11: Escalader selon la criticité
D12: Communiquer avec les parties prenantes
D13: Clôturer et documenter l’incident
B14: Processus de gestion des problèmes | C14: Identifier et corriger les causes racines des incidents récurrents ou majeurs pour éviter leur réapparition. | D14: Identifier les problèmes à partir d’incidents récurrents | E14: Direction Core Operations(iSOC) IT Operations(iSOC)
D15: Réaliser les analyses de cause racine (RCA)
D16: Identifier les erreurs connues et proposer des solutions
D17: Suivre la mise en œuvre des actions correctives
D18: Mettre à jour la base de connaissances
B19: Processus de Gestion de changement | C19: Piloter les modifications N&IS (configurations, migrations, Ajout , Suppression etc). | D19: Justifier le changement | E19: Direction Core Operations Directions Field Operations Direction Energie Direction Field Network IT Operations Gestionnaires plateformes IT
D20: soumettre la demande de changement
D21: faire valider par le comité de changement
D22: planifier la fenêtre de maintenance
D23: exécuter le changement
D24: réaliser des tests après changement
D25: Suivre les KPI de performance après le changement
D26: Cloturer l'activité
D27: mettre à jour la documentation
B28: Processus de maintenance préventive | C28: Exécuter les actions techniques nécessaires pour prévenir les défaillances et maintenir en bon etat les infrastructures. | D28: Planifier les maintenances préventives | E28: Direction Core Operations Directions Field Operations Direction Energie Direction Field Network IT Operations Gestionnaires plateformes IT
D29: Réaliser les opérations de vérification régulières
D30: Intervenir sur site
D31: Mettre à jour les historiques d’intervention
B32: Processus de gestion des accès techniques | C32: Gérer les droits d’accès physiques aux infrastructures réseau et IT pour garantir la sécurité et la traçabilité des interventions. | D32: Vérifier les habilitations des personnes entrant sur site | E32: Direction Infrastructure Infrastructure IT Direction Field Operations Direction Core Operations Cybersécurité
D33: Enregistrer et valider ou faire valider les demandes d'accès
D34: Tenir à jour le registre d’accès
D35: Auditer périodiquement les accès
D36: Appliquer les recommandations après Audit
B40: =COUNTA(B4:B36) -> 6 | D40: =COUNTA(D4:D36) -> 33

Sheet Gestion budgétaire
A2: Macro 04: Gestion budgétaire(Investissement et Opérationnel)
A4: Description Détaillée | B4: Process | C4: Description du process | D4: Identification des tâches | E4: Directions concernées
A5: Ce macro-processus regroupe l’ensemble des processus liés à la gestion financière des activités techniques réseau et IT. Elle vise à planifier, exécuter, suivre et ajuster les budgets CAPEX (investissements) et OPEX (fonctionnement) en garantissant leur alignement avec les orientations stratégiques, les capacités techniques et les contraintes économiques. Elle comprend l’identification des besoins budgétaires, l’élaboration des prévisions, l’allocation des ressources, le suivi des consommations réelles, l’analyse des écarts, et la mise en place de plans d’optimisation. Elle s’appuie sur une collaboration étroite avec les équipes financières et les responsables techniques. Elle mobilise les domaines eTOM sur le Financial & Asset Management et Enterprise Strategic Planning. | B5: Processus d’identification des besoins budgétaires | C5: Recenser et qualifier les besoins financiers liés aux projets, opérations et évolutions techniques à venir. | D5: Identifier les besoins par Departements/Services/Directions | E5: CTIO Direction Technical business support G&PMO Toutes les Directions Network &IS
D6: Consolider les expressions de besoins
D7: Estimer les coûts prévisionnels CAPEX/OPEX
D8: Classer les besoins par priorité et criticité
B9: Processus d'éléboration du budget prévisionnelle | C9: Élaborer les budgets annuels et pluriannuels en alignement avec les besoins, orientations stratégiques et les contraintes économiques. | D9: Collecter les projections financières des Departements/Services/Directions | E9: CTIO Direction Technical business support G&PMO Toutes les Directions Network &IS
D10: Consolider les enveloppes CAPEX et OPEX
D11: Arbitrer les priorités budgétaires
D12: Identifier et prendre en compte les besoins budgétaires croisés avec les directions partenaires impactées (et impactantes)
D13: Soumettre les budgets aux instances de validation
B14: Processus de validations des budgets | C14: Elaborer les budgets et leurs synthèses conformement aux canevas pré-définis | D14: Préparer les synthèses du projet de budget et les commentaires | E14: CTIO Direction Technical business support G&PMO Toutes les Directions Network &IS
D15: Faire la navette budgétaire / présentation et recommentdations
D16: Mettre à jour du budget en prenant en compte les recommendations
D17: Soumettre à la valitation finale
B18: Processus d’allocation et ventilation budgétaire | C18: Répartir les ressources financières par projet, activité ou entité pour assurer un usage optimal des fonds disponibles. | D18: Définir les règles de ventilation budgétaire | E18: CTIO Direction Technical business support G&PMO Toutes les Directions Network &IS
D19: Allouer les enveloppes par projet ou besoin
D20: Notifier les affectations aux parties prenantes
D21: Mettre à jour les référentiels de suivi budgétaire
B22: Processus de suivi et pilotage de la consommation budgétaire | C22: Contrôler l’exécution des dépenses par rapport aux prévisions pour assurer la maîtrise financière continue. | D22: Suivre la consommation budgétaire en temps réel | E22: CTIO Direction Technical business support G&PMO Toutes les Directions Network &IS
D23: Comparer dépenses engagées vs prévisionnelles
D24: Identifier les écarts significatifs
D25: Réaliser les reportings périodiques
B26: Processus d’analyse et justification des écarts | C26: Analyser les écarts budgétaires, déterminer les causes et proposer des ajustements pour corriger les dérives. | D26: Collecter les données de dépenses réelles | E26: CTIO Direction Technical business support G&PMO Toutes les Directions Network &IS
D27: Analyser les écarts par ligne budgétaire
D28: Identifier les facteurs d’écart (retard, surcoût etc...)
D29: Proposer des mesures correctives
B30: Processus d’optimisation et d’arbitrage budgétaire | C30: Réaliser des ajustements et réaffectations pour optimiser l’usage des ressources financières en cours d’exercice. | D30: Identifier les budgets sous-utilisés ou en tension | E30: CTIO Direction Technical business support G&PMO Toutes les Directions Network &IS
D31: Réévaluer les priorités d’investissement
D32: Proposer des réallocations budgétaires
D33: Mettre à jour les prévisions financières
B34: Processus de contribution aux exercices financiers transverse globaux | C34: Participer aux processus financiers transverses et globale de l’entreprise (forecasts, clôtures, business plan). | D34: Transmettre les données budgétaires consolidées | E34: CTIO Direction Technical business support G&PMO Toutes les Directions Network &IS
D35: Participer aux comités financiers
D36: Intégrer les exigences du contrôle de gestion
D37: Réviser les hypothèses économiques partagées
B39: =COUNTA(B5:B37) -> 8 | D39: =COUNTA(D5:D37) -> 33

Sheet Gouvernance N&IS
A2: Macro 02: Gouvernance Networks & IS
A4: Description Détaillée | B4: Process | C4: Description du process | D4: Identification des tâches | E4: Directions concernées
A5: Le macro-processus de Gouvernance fournit le cadre essentiel au pilotage organisationnel en structurant les documents, les responsabilités et les rôles. Il garantit une base claire et cohérente permettant de maîtriser les risques, assurer la continuité et maintenir la conformité globale de l’organisation. Ce macro-processus repose sur plusieurs processus complémentaires. La structuration documentaire et la définition des responsabilités établissent un référentiel clair et standardisé, tandis que la gestion des risques organisationnels permet d’identifier, analyser et maîtriser les menaces pouvant impacter la performance. Le processus PCA/PRA renforce cette maîtrise en assurant la continuité des services critiques et la capacité de reprise après incident majeur. Par ailleurs, le suivi des politiques, processus et procédures garantit le contrôle régulier de leur application, alors que l’évaluation périodique mesure leur pertinence et leur efficacité. Enfin, le processus d’amélioration assure l’évolution continue du système documentaire et opérationnel en intégrant les retours d’expérience, les audits et les actions correctives. Ainsi, le macro-processus Gouvernance consolide la stabilité et la performance de l’organisation en assurant une maîtrise rigoureuse, une résilience opérationnelle et une amélioration continue. Il joue un rôle central dans l’alignement durable des pratiques avec les exigences internes et réglementaires. | B5: Processus de structuration des documents, des responsabilités, et des rôles . | C5: Définir, et formaliser les documents , responsabilités, autorités, et roles de gouvernance dans les opérations et projets Network & IS , | D5: Identifier les acteurs internes et externes impliqués dans la gouvernance | E5: Direction PMO & Gouvernance
D6: Définir les rôles, responsabilités et niveaux d’autorité (matrice RACI)
D7: Élaborer la cartographie documentaire (PPP, instructions, fiches)
D8: Structurer et normaliser les formats documentaires
D9: Mettre en place un dispositif de gestion documentaire (validation, diffusion, archivage)
D10: Actualiser périodiquement selon les évolutions organisationnelles
B11: Processus de gestion des risques organisationnels | C11: Identifier, évaluer, traiter et surveiller les risques d’ordre organisationnel impactant les projets ou la performance des SI & Réseaux | D11: Identifier les risques organisationnels (structure, ressources, conformité, dépendances) | E11: Direction PMO & Gouvernance
D12: Évaluer la probabilité, l’impact et la criticité (grille P×I)
D13: Élaborer la matrice des risques et définir les plans d’atténuation
D14: Assigner les responsables de suivi et de mise en œuvre
D15: Mettre à jour le registre des risques
D16: Suivre les indicateurs d’efficacité et rendre compte au comité de gouvernance
B17: Processus de gestion de la continuité et de reprise d’activité (PCA/PRA) | C17: Encadrer la définition, la mise en œuvre et la mise à jour des plans de continuité (PCA) et de reprise d’activité (PRA) pour les services Network & IS. Aligné sur les standards ISO 22301 et ITIL, il vise à garantir la résilience opérationnelle en cas d’incident majeur, via des procédures de secours formalisées et régulièrement testées. | D17: Analyser et formaliser le PCA/PRA | E17: Direction PMO & Gouvernance
D18: Structurer les rôles et les responsabilités dans le PCA/PRA
D19: Documenter et communiquer les plans
D20: Tests et exercices réguliers
D21: Maintien en condition opérationnelle
D22: Amélioration continue et retour d’expérience
B23: Processus de suivi des Politiques, Processus et Procédures | C23: assurer le contrôle régulier de la mise en œuvre effective des politiques, processus et procédures Network & IS. Garantir la conformité opérationnelle et la cohérence entre pratiques terrain et exigences normatives. | D23: Élaborer le plan annuel de suivi et d’audit des PPP | E23: Direction PMO & Gouvernance
D24: Collecter les rapports d’application et de conformité
D25: Contrôler l’exécution effective sur le terrain (revues, inspections, audits)
D26: Identifier les écarts et non-conformités
D27: Documenter les constats et définir des actions correctives
D28: Communiquer les résultats aux responsables concernés
B29: Processus d’évaluation des Politiques, Processus et Procédures | C29: Mesurer la pertinence, l’efficacité et la cohérence des PPP au regard des objectifs stratégiques, des exigences réglementaires , les meilleures pratiques et les seuil defini pour les KPI .Détecter les faiblesses structurelles et d’orienter les décisions d’amélioration. | D29: Définir les critères d’évaluation (pertinence, efficacité, cohérence) | E29: Direction PMO & Gouvernance
D30: Collecter les retours d’expérience et données de performance
D31: Analyser les écarts récurrents ou redondances documentaires
D32: Mesurer la performance par des indicateurs (KPI, taux de conformité)
D33: Rédiger le rapport d’évaluation global
D34: Prioriser les axes d’amélioration
B35: Processus d’amélioration des Politiques, Processus et Procédures | C35: Piloter l’amélioration continue du système de gouvernance Network & IS. Garantir l’alignement permanent des PPP sur les standards ISO, ITIL et les besoins opérationnels, tout en clôturant le cycle PDCA (Plan–Do–Check–Act). | D35: Identifier les axes d’amélioration issus des évaluations, audits et REX | E35: Direction PMO & Gouvernance
D36: Réviser ou élaborer les documents (PPP) concernés
D37: Valider, documenter et diffuser les nouvelles versions
D38: Former les utilisateurs aux mises à jour
D39: Vérifier l’efficacité post-mise en œuvre
D40: Capitaliser les leçons apprises dans la base de connaissance
B43: =COUNTA(B5:B40) -> 6 | D43: =COUNTA(D5:D40) -> 36

Sheet Projets N&IS
A2: Macro 09: Management des Projets Networks & IS
A4: Description Détaillée | B4: Process | C4: Description du process | D4: Identification des tâches | E4: Directions concernées
A5: Le macro-processus Management des Projets Networks & IS regroupe l’ensemble des pratiques, méthodologies et processus permettant de piloter avec rigueur les projets N&IS. Il couvre tout le cycle de vie du projet, depuis l’initiation jusqu’à la clôture, en intégrant les standards du PMBOK 6&7, adaptés au contexte des projets d’infrastructure, d’évolution réseau, de transformation digitale ou d’intégration SI. Il repose sur une gestion structurée de l’intégration, du périmètre, du calendrier, des coûts (CAPEX/OPEX), de la qualité, des ressources, des communications, des risques, des approvisionnements et de la gouvernance des parties prenantes. L’objectif est d’assurer que les projets Network & IS sont livrés dans les délais, respectent les exigences techniques, sécuritaires et réglementaires, tout en optimisant les ressources mobilisées. Chaque projet est formalisé à travers une charte projet validée en comité de gouvernance, un kick-off officiel, une planification intégrée, un pilotage par jalons, un suivi des livrables techniques, une gestion active des risques, et une coordination inter-équipes (ingénierie, déploiement, exploitation, partenaires etc...). Des revues régulières, un reporting structuré et une gestion de la documentation projet garantissent la traçabilité et l’amélioration continue. Ce macro inclut également les processus de gestion de la connaissance (capitalisation) et de gestion du changement nécessaires à la réussite durable des projets et à la transition fluide vers l’exploitation. | B5: Processus d’initiation des projets | C5: Définir la justification, les objectifs, et obtenir la validation du lancement. | D5: Nommer le chef de projet et définir les responsabilités | E5: DGouv&PMO DNE IT – Product & Project Delivery
D6: Rédiger la charte projet (périmètre, objectifs, budget initial, sponsor)
D7: Obtenir la validation formelle du lancement par le comité de pilotage
D8: Lancer le Kick‑off
B9: Processus de gestion de l’intégration | C9: Assurer la cohérence entre les plans techniques, financiers, qualité et risques pour garantir l’alignement stratégique global. | D9: Élaborer le plan de management du projet (PMP) | E9: DNE IT – Product & Project Delivery DGouv&PMO
D10: Coordonner les contributions inter-domaines (Radio, Transmission, Core, IT, etc.) & les plans complementaires (scope, coûts, planning, qualité…)
D11: Assurer la cohérence des plans techniques et financiers
D12: Gérer les interdépendances entre processus
D13: Contrôler la cohérence des livrables
B14: Processus de gestion du périmètre | C14: Définir les livrables, limites et exclusions du projet, et contrôler l'évolution . | D14: Recueillir les exigences métiers et techniques | E14: DNE IT – Product & Project Delivery DGouv&PMO
D15: Définir les critères d’acceptation des livrables
D16: Structurer la décomposition du projet en lots de travail (WBS)
D17: Obtenir la validation du périmètre
D18: Surveiller les dérives fonctionnelles ou techniques
D19: Valider la conformité du périmètre en clôture
B20: Processus de gestion du planning | C20: Planifier, estimer et piloter les délais de réalisation des differentes etapes du projet | D20: Identifier les activités et jalons | E20: DNE IT – Product & Project Delivery DGouv&PMO
D21: Estimer les durées et séquencer les tâches
D22: Établir le calendrier (Gantt, jalons)
D23: Surveiller l’avancement et réviser le planning
B24: Processus de gestion des coûts | C24: Planifier, budgétiser et contrôler les coûts pour garantir le respect des contraintes financières | D24: Établir le budget global et la ligne de base des coûts | E24: DNE IT – Product & Project Delivery DGouv&PMO
D25: Suivre les engagements contractuels, la consommation budgétaire
D26: Contrôler les écarts financiers & ajuster les prévisions
D27: Élaborer les rapports budgétaires
B28: Processus de gestion de la qualité | C28: Garantir la conformité des livrables aux exigences de qualité définies et attendues | D28: Identifier les standards qualité applicables (techniques, HSE, service…) | E28: DNE IT – Product & Project Delivery DGouv&PMO
D29: Élaborer le plan qualité projet
D30: Réaliser les audits, tests et revues qualité
D31: Gérer les non-conformités et améliorer les livrables
D32: Valider la conformité des livrables finaux
B33: Processus de gestion des ressources | C33: Mobiliser & optimiser la planification et l’affectation des ressources humaines, matérielles et logistiques. nécessaires au projet | D33: Identifier les besoins en ressources (internes/externes) | E33: DNE IT – Product & Project Delivery DGouv&PMO
D34: Planifier les charges et affectations
D35: Gerer la charge, la performance et la disponibilité
D36: Arbitrer et Gérer les conflits
D37: Superviser les aspects logistiques et matériels
B38: Processus de gestion de la communication | C38: Assurer une communication fluide, claire , structurée et traçable tout au long du projet entre toutes les parties prenantes | D38: Définir la stratégie de communication projet | E38: DNE IT – Product & Project Delivery DGouv&PMO
D39: Diffuser les rapports executifs et technique du projet
D40: Animer les réunions et comités
D41: Documenter et assurer la traçabilité des décisions
D42: Gérer les flux d’information et les escalades
...

Sheet Performance & optimisation
A1: Macro 08: Performance & Optimisation Networks & IS
A3: Description Détaillée | B3: Process | C3: Description du process | D3: Identification des tâches | E3: Directions concernées
A4: Cette macro couvre l’ensemble des activités visant à surveiller, analyser, maintenir et améliorer en continu la performance des infrastructures techniques et des services associés, dans une logique proactive et d’optimisation. Elle s’applique aux réseaux fixes, mobiles, plateformes IT, et services métiers ou techniques. L’objectif est de garantir un bon niveau de qualité de service (QoS), de disponibilité, et d’efficacité opérationnelle, tout en anticipant les dégradations et en adaptant les ressources aux évolutions des usages. Elle intègre la collecte continue de métriques (temps de réponse, débit, disponibilité, erreurs), la détection de tendances ou d’anomalies, la gestion de la capacité (capacity management), l’analyse de la performance bout en bout, ainsi que la mise en œuvre de plans d’optimisation ou d’amélioration continue. Cette macro est également responsable de la mise en place de KPIs et dashboards décisionnels, du support aux métiers sur les sujets de qualité perçue, et de la contribution aux projets d’évolution en apportant une vision objective des performances existantes. Alignée avec les processus Performance Management, Service Quality Management du referentiel eTOM, ainsi qu’avec les bests pratices ITIL de Monitoring & Event Management, elle est essentielle pour piloter la performance technique et garantir l’alignement des capacités N&IS avec les attentes métiers. | B4: Process de supervision des performances | C4: Monitorer en permanence les KPIs, corréler les événements et analyser les tendances afin de maintenir un réseau performant et fiable. | D4: Mettre en place les outils de supervision de performance (OSS, probes, sondes, etc.) | E4: Direction Performance & Optimisation
D5: Definir les KPI par domaines
D6: Configurer les seuils d’alerte et de performance
D7: Suivre les SLA, taux de disponibilité, taux de plainte
D8: Générer les rapports de performance périodiques
B9: Processus de mesure de la performance | C9: Collecter des données terrain et systèmes via OSS, drive tests ou outils de sondes afin d’évaluer objectivement la performance du réseau et des services . | D9: Planifier les campagnes de mesures (zones, technologies, objectifs) | E9: Direction Performance & Optimisation
D10: Configurer les outils de collecte (OSS KPIs, sondes, mobiles de test, scanners RF)
D11: Réaliser les campagnes de drive tests ou extraire les données OSS
D12: Consolider et nettoyer les données collectées
B13: Process d’analyse de performance | C13: Analyser les données collectées pour détecter proactivement les dégradations de la QoS, ou variations anormales et autres dysfonctionnements | D13: Extraire et analyser les KPIs (trafic, disponibilité, taux d'erreur, etc.) | E13: Direction Performance & Optimisation
D14: Établir des dashboards analytiques par domaine (radio, transmission, core, IT etc...)
D15: Corréler les événements avec les alarmes, incidents et changements
D16: Analyser les écarts par rapport aux seuils cibles
D17: Classifier les degradations par criticité
B18: Processus d’evaluation de la QOE | C18: Évaluer l’expérience utilisateur et la qualité des services fournis à travers des mesures techniques et subjectives. | D18: Definir et Analyser les indicateurs QoE par service et par domaine (voix, data, IT apps) | E18: Direction Performance & Optimisation
D19: Identifier les anomalies ou dégradations par segment de réseau
D20: Corréler les résultats avec les tickets ou plaintes clients
D21: Identifier les dégradations ressenties non détectées
B22: Processus d’optimisation de la configuration | C22: Identifier et mettre en œuvre des actions d’optimisation technique sur les éléments du réseau, IT et services. | D22: Auditer les configurations existantes (radio, core, IP, IT etc...) | E22: Direction Performance & Optimisation
D23: Comparer avec les best practices et les recommandations constructeur
D24: Appliquer les modifications correctives ou préventives
D25: Suivre les impacts post-modification
B26: Processus de capacity planning | C26: Planifier l’évolution des ressources techniques pour anticiper les hausses de charge et éviter la saturation. | D26: Projeter les évolutions de trafic et de charge applicative | E26: Direction Performance & Optimisation Direction Network Engineering
D27: Élaborer des modèles de prévision et de dimensionnement
D28: Déterminer les investissements nécessaires
D29: Intégrer ces besoins dans les roadmaps et plans de déploiement
B33: =COUNTA(B4:B29) -> 6 | D33: =COUNTA(D4:D29) -> 26

Sheet Sécurité & Résilience SI
A1: Description Détaillée | B1: Process | C1: Description du process | D1: Identification des tâches | E1: Directions concernées
A2: Ce macro-processus regroupe toutes les activités nécessaires pour assurer la sécurité, la protection, la prévention et la résilience des infrastructures Networks (mobile, fixe, transmission) et IS (serveurs, plateformes, services). Elle vise à anticiper, détecter, répondre et capitaliser sur les incidents et/ou attaques, tout en maintenant la continuité des services techniques et métier. Elle inclut la définition des politiques de sécurité, la gestion des risques, la surveillance des menaces, la réponse aux incidents de sécurité, la gestion des vulnérabilités, le chiffrement, l’authentification, la sécurité des accès, la résilience (plans de reprise, redondance) et le reporting. Elle s’appuie sur les domaines Security & Assurance d’eTOM, les pratiques ITIL Security Management, Information Security, Risk Management, ainsi que les cadres normatifs tels que ISO 27001, UIT, RGPD. L’objectif est de garantir que les infrastructures et services soient protégés, résilients, et conformes, tout en minimisant l’impact sur les opérations. | B2: Processus de définition des politiques de sécurité | C2: Définir, maintenir et diffuser les politiques, standards et orientations de sécurité pour le parc N&IS. | D2: Élaborer les politiques en conformité avec ISO 27001 et exigences réglementaires | E2: CISO
D3: Valider les politiques avec la gouvernance N&IS
D4: Diffuser et sensibiliser les équipes à ces politiques
D5: Mettre à jour périodiquement les politiques selon retours et audits
B6: Processus de gestion des risques & évaluations de la sécurité | C6: Identifier, évaluer et prioriser les risques de sécurité pesant sur les infrastructures et services. | D6: Réaliser des analyses de risques (impact/probabilité) | E6: CISO
D7: Cartographier les scénarios de menace critiques
D8: Définir les mesures de réduction de risque et contrôles
D9: Suivre la mise en œuvre des recommandations et leur efficacité
B10: Gestion des identités et des accès (IAM) | C10: Ce processus s'assure que seules les personnes autorisées ont accès aux systèmes et aux données sensibles. | D10: Gerer les identités : Créer, gerer et supprimer les comptes utilisateurs | E10: Cyber-Security
D11: Gerer les accès : Attribuer les droits d'accès basés sur les rôles des utilisateurs (RBAC – Role-Based Access Control).
D12: Authentifier et autoriser : Mettre en place un mécanismes d'authentification solides (multi-facteurs, biométrie, etc.) et gerer les autorisations d'accès.
D13: Surveiller les accès : Suivre et analyser des activités d'accès pour détecter toute tentative d'accès non autorisé ou abusif.
D14: Révoquer les accès : Gerer les comptes inactifs ou obsolètes, et révoquer les accès des utilisateurs lorsqu'ils ne sont plus autorisés.
B15: Processus Protection des données | C15: Assurer la mise en place de mesures de protection pour garantir la confidentialité, l'intégrité et la disponibilité des données | D15: Chiffrement des données : Mise en place de mécanismes pour chiffrer les données sensibles, tant en transit qu'au repos. | E15: Cyber-Security
D16: Contrôle de la confidentialité des données : Application de politiques de confidentialité des données, telles que la classification des données et la gestion des données personnelles.
D17: Protection contre la perte de données (DLP) : Mise en œuvre de solutions pour prévenir la fuite ou la perte de données sensibles (ex. dispositifs de contrôle des fuites de données).
D18: Sauvegardes et récupération : Assurer la mise en place de sauvegardes régulières et de plans de récupération des données en cas de sinistre.
B19: Processus de Sécurisation des infrastructures et des applications | C19: Mettre en place des mecanisnismes de protections adaptés pour securser les infrastructures et les applications . | D19: Sécuriser les endpoints : Protection des dispositifs utilisateurs (ordinateurs de bureau, portables, téléphones mobiles, etc.) via des solutions antivirus, EDR, etc. | E19: Cyber-Security
D20: Sécuriser le réseau : Mise en place de pare-feu, systèmes de détection et de prévention des intrusions (IDS/IPS), segmentation du réseau, etc.
D21: Sécuriser les applications : Assurer la sécurité des applications via des tests de sécurité (ex. tests de pénétration, analyse de vulnérabilités) et la mise en œuvre de pratiques de codage sécurisé.
D22: Contrôler les périphériques externes : Gestion des risques liés aux périphériques externes (USB, périphériques réseau, etc.), avec des politiques d'accès et des outils de contrôle des périphériques
B23: Gestion des vulnérabilités et des patchs | C23: Identifier, qualifier et traiter les vulnérabilités sur les infrastructures, les systèmes et les applications. | D23: Réaliser des scans de vulnérabilité réguliers | E23: Cyber-Security
D24: Prioriser les vulnérabilités en fonction de leur criticité
D25: Déployer les correctifs ou mesures compensatoires
D26: Suivi des vulnérabilités : Assurer le suivi des vulnérabilités sur le long terme et leur résolution dans les délais appropriés.
B27: Processus de surveillance et détection d’intrusions | C27: Surveiller les infrastructures pour détecter les attaques, intrusions ou comportements anormaux. | D27: Mettre en place des outils IDS/IPS, SIEM | E27: Cyber-Security
D28: Collecter et corréler les logs de sécurité
D29: Détecter les incidents potentiels et anomalies
D30: Escalader et déclencher les réponses selon niveau de menace
B31: Processus de réponse aux incidents de sécurité | C31: Traiter les incidents de sécurité (détection, confinement, résolution, restauration) afin de limiter l’impact. | D31: Activer le plan de réponse à incident (IRP) | E31: CISO
D32: Contenir l’attaque ou la faille
D33: Identifier l’origine et l’étendue de la menace
D34: Restaurer les services affectés
D35: Documenter l’incident et proposer des leçons après le RCA
B36: Processus de résilience et reprise après sinistre | C36: Mettre en place les mesures de continuité, redondance et plans de reprise pour garantir la résilience des services. | D36: Définir les plans de reprise (DRP) et continuité (BCP) | E36: CISO
D37: Tester périodiquement les plans (exercices, simulations)
D38: Mettre en place la redondance (sites, liaisons)
D39: Tester périodiquement les redondances
D40: Assurer le basculement et rétablissement des services
...

Sheet Stratégie & Evolution des infra
A1: Macro 01: Stratégie & Évolution des Infrastructures et Services
A3: Description Détaillée | B3: Process | C3: Description du process | D3: Identification des tâches | E3: Directions concernées
A4: Cette macro couvre le pilotage globale du cycle de vie des ressources (IT, réseau, plateformes) et des services (voix, data, BSS/OSS), depuis leur conception jusqu’à leur retrait. Elle vise à garantir une cohérence d’ensemble des choix techniques et à structurer l’évolution des capacités et des fonctions techniques en anticipant les ruptures technologiques. Elle comprend : - L’analyse prospective et continue des besoins métiers et des usages - L’évaluation des tendances technologiques (cloud, 5G, edge, automatisation, IA, etc.) - La définition et la révision régulière des architectures cibles et des capacités de services - L’élaboration de feuilles de route structurées et arbitrées techniquement et budgétairement - La formalisation des principes directeurs (standards, normes, orientations techniques) - La coordination des trajectoires d’évolution des services et infrastructures (ressources physiques et logiques) - L’intégration de la résilience, de la scalabilité et de la maintenabilité dès la conception stratégique - L’articulation avec la gestion des risques, des investissements et des capacités | B4: Processus d’évaluation de l’existant | C4: Évaluer l’état actuel des infrastructures, des services et de leurs performances pour établir une base de référence. | D4: Cartographier les infrastructures techniques et fonctionnelles existant | E4: Direction Network Engineering DSI
D5: Analyser la performance et l’obsolescence des composants
D6: Identifier les interdépendances critiques
D7: Évaluer les capacités et les goulots d’étranglement
B8: Processus de veille technologique et stratégique | C8: Anticiper les innovations, ruptures ou menaces technologiques impactant les orientations stratégiques. | D8: Effectuer une veille ciblée sur les tendances techniques | E8: CTIO Direction Network Engineering DSI
D9: Analyser les signaux faibles et les ruptures potentielles
D10: Évaluer les impacts des innovations sur l’existant
D11: Diffuser les résultats de la veille auprès des décideurs
B12: Processus d'elaboration des plans Directeur | C12: Construire les feuilles de route d'evolution à moyen et long terme pour planifier les transformation technologiques | D12: Consolider les besoins par domaine | E12: Direction Network Engineering DSI
D13: Definir les priorités d'investissemnt par lot ou par phase
D14: Elaborer le plan directeur technique par infrastructure
D15: Formaliser le plan Directeur et le soumettre aux instences de gouvernance ,
B16: Processus de gestion du cycle de vie des infrastructures | C16: Définir et encadrer la création, l’évolution et le retrait des infrastructures tout au long de leur cycle de vie. | D16: Définir les étapes du cycle de vie d’un service | E16: Direction Network Engineering DSI
D17: Identifier les critères d’entrée/sortie de chaque phase
D18: Planifier les remplacement , migration ou refontes
D19: Superviser la cohérence avec les besoins utilisateurs
B20: Processus de pilotage de la revue stratégique | C20: Réviser régulièrement les choix stratégiques en fonction de l’évolution des contextes internes et externes. | D20: Organiser les revues périodiques de stratégie technique | E20: Direction Network Engineering DSI
D21: Mesurer les écarts entre planification et réalisation
D22: Actualiser les objectifs et les feuilles de route
D23: Coordonner les arbitrages inter-domaines
B26: =COUNTA(B4:B23) -> 5 | D26: =COUNTA(D4:D23) -> 20

Sheet Support et Assistance IT
A2: Macro 11: Support & Assistance IT Network & IS
A4: Description Détaillée | B4: Process | C4: Description du process | D4: Identification des tâches | E4: Directions concernées
